<?xml version="1.0" encoding="utf-8"?>
<robot
  name="roller_3rd"
  xmlns:xacro="http://ros.org/wiki/xacro">

  <xacro:include filename="$(find roller_3rd)/urdf/roller_3rd.gazebo.xacro"/>
  
  <xacro:property name="PI" value="3.14159265"/>

  <!-- 定义变量关节阻尼<damping>和摩擦<friction> -->
  <xacro:property name="Damping" value="10"/>
  <xacro:property name="Friction" value="1.0"/>

  <link
    name="base_link">
    <inertial>
      <origin
        xyz="0.00165468528771355 0 3.46944695195361E-18"
        rpy="0 0 0" />
      <mass
        value="5.71725666117692" />
      <inertia
        ixx="0.0225933299115147"
        ixy="-7.46338336817294E-18"
        ixz="-8.65561792975494E-20"
        iyy="0.0444190381762262"
        iyz="-5.95570041038183E-20"
        izz="0.0574836069857794" />
    </inertial>
    <visual>
      <origin
        xyz="0 0 0"
        rpy="0 0 0" />
      <geometry>
        <mesh
          filename="package://roller_3rd/meshes/base_link.STL" />
      </geometry>
      <material
        name="">
        <color
          rgba="1 1 1 1" />
      </material>
    </visual>
    <collision>
      <origin
        xyz="0 0 0"
        rpy="0 0 0" />
      <geometry>
        <mesh
          filename="package://roller_3rd/meshes/base_link.STL" />
      </geometry>
    </collision>
  </link>
  <link
    name="leg1_1_link">
    <inertial>
      <origin
        xyz="0.0229508358714046 5.55111512312578E-17 9.54097911787244E-18"
        rpy="0 0 0" />
      <mass
        value="0.350969420203415" />
      <inertia
        ixx="0.000303791179644144"
        ixy="5.42101086242752E-20"
        ixz="-9.10079262163607E-20"
        iyy="0.00119023844034398"
        iyz="-5.26721073892596E-21"
        izz="0.00101824231652429" />
    </inertial>
    <visual>
      <origin
        xyz="0 0 0"
        rpy="0 0 0" />
      <geometry>
        <mesh
          filename="package://roller_3rd/meshes/leg1_1_link.STL" />
      </geometry>
      <material
        name="">
        <color
          rgba="1 1 1 1" />
      </material>
    </visual>
    <collision>
      <origin
        xyz="0 0 0"
        rpy="0 0 0" />
      <geometry>
        <mesh
          filename="package://roller_3rd/meshes/leg1_1_link.STL" />
      </geometry>
    </collision>
  </link>
  <joint
    name="leg1_1_joint"
    type="continuous">
    <origin
      xyz="-0.147803901741747 -0.0996390580196406 0"
      rpy="0 0 -2.55359005004223" />
    <parent
      link="base_link" />
    <child
      link="leg1_1_link" />
    <axis
      xyz="0 0 1" />
    <limit
      lower="0"
      upper="6.2"
      effort="0"
      velocity="3" />
    <dynamics damping="${Damping}" friction="${Friction}"/>
  </joint>
  <link
    name="leg1_2_Link">
    <inertial>
      <origin
        xyz="0.0200223800027242 5.55111512312578E-17 -0.015"
        rpy="0 0 0" />
      <mass
        value="0.111205750411731" />
      <inertia
        ixx="2.18856469213198E-05"
        ixy="1.6940658945086E-20"
        ixz="6.79741766887558E-21"
        iyy="0.000444744745767282"
        iyz="-9.23153143079456E-21"
        izz="0.000444744745767282" />
    </inertial>
    <visual>
      <origin
        xyz="0 0 0"
        rpy="0 0 0" />
      <geometry>
        <mesh
          filename="package://roller_3rd/meshes/leg1_2_Link.STL" />
      </geometry>
      <material
        name="">
        <color
          rgba="1 1 1 1" />
      </material>
    </visual>
    <collision>
      <origin
        xyz="0 0 0"
        rpy="0 0 0" />
      <geometry>
        <mesh
          filename="package://roller_3rd/meshes/leg1_2_Link.STL" />
      </geometry>
    </collision>
  </link>
  <joint
    name="leg1_2_joint"
    type="prismatic">
    <origin
      xyz="0.270650697408827 0 0.015"
      rpy="0 0 0" />
    <parent
      link="leg1_1_link" />
    <child
      link="leg1_2_Link" />
    <axis
      xyz="-1 0 0" />
    <limit
      lower="0"
      upper="0.2"
      effort="0"
      velocity="3" />
    <dynamics damping="${Damping}" friction="${Friction}"/>
  </joint>
  <link
    name="leg1_3_Link">
    <inertial>
      <origin
        xyz="2.60208521396521E-18 -1.11022302462516E-16 2.22044604925031E-16"
        rpy="0 0 0" />
      <mass
        value="0.440608369665969" />
      <inertia
        ixx="0.00059757510135947"
        ixy="-1.13051991884092E-19"
        ixz="-3.71158038358037E-20"
        iyy="0.00059757510135947"
        iyz="-2.98155597433514E-19"
        izz="0.00112905894726905" />
    </inertial>
    <visual>
      <origin
        xyz="0 0 0"
        rpy="0 0 0" />
      <geometry>
        <mesh
          filename="package://roller_3rd/meshes/leg1_3_Link.STL" />
      </geometry>
      <material
        name="">
        <color
          rgba="1 1 1 1" />
      </material>
    </visual>
    <collision>
      <origin
        xyz="0 0 0"
        rpy="0 0 0" />
      <geometry>
        <mesh
          filename="package://roller_3rd/meshes/leg1_3_Link.STL" />
      </geometry>
    </collision>
  </link>
  <joint
    name="leg1_3_joint"
    type="continuous">
    <origin
      xyz="0.105 0 -0.0150000000000001"
      rpy="0 -1.5707963267949 0" />
    <parent
      link="leg1_2_Link" />
    <child
      link="leg1_3_Link" />
    <axis
      xyz="0 0 -1" />
    <dynamics damping="${Damping}" friction="${Friction}"/>
  </joint>
  <link
    name="leg2_1_Link">
    <inertial>
      <origin
        xyz="0.0229508358714045 5.55111512312578E-17 5.20417042793042E-18"
        rpy="0 0 0" />
      <mass
        value="0.350969420203415" />
      <inertia
        ixx="0.000303791179644144"
        ixy="-2.98155597433514E-19"
        ixz="-1.5297854950715E-20"
        iyy="0.00119023844034398"
        iyz="7.68595383024475E-22"
        izz="0.0010182423165243" />
    </inertial>
    <visual>
      <origin
        xyz="0 0 0"
        rpy="0 0 0" />
      <geometry>
        <mesh
          filename="package://roller_3rd/meshes/leg2_1_Link.STL" />
      </geometry>
      <material
        name="">
        <color
          rgba="1 1 1 1" />
      </material>
    </visual>
    <collision>
      <origin
        xyz="0 0 0"
        rpy="0 0 0" />
      <geometry>
        <mesh
          filename="package://roller_3rd/meshes/leg2_1_Link.STL" />
      </geometry>
    </collision>
  </link>
  <joint
    name="leg2_1_joint"
    type="continuous">
    <origin
      xyz="-0.147803901741747 0.0996390580196404 0"
      rpy="0 0 2.55359005004223" />
    <parent
      link="base_link" />
    <child
      link="leg2_1_Link" />
    <axis
      xyz="0 0 1" />
    <limit
      lower="0"
      upper="6.2"
      effort="0"
      velocity="3" />
    <dynamics damping="${Damping}" friction="${Friction}"/>
  </joint>
  <link
    name="leg2_2_Link">
    <inertial>
      <origin
        xyz="0.020022380002724 0 -0.015"
        rpy="0 0 0" />
      <mass
        value="0.111205750411731" />
      <inertia
        ixx="2.18856469213197E-05"
        ixy="6.52215369385811E-20"
        ixz="2.6318863250598E-20"
        iyy="0.000444744745767282"
        iyz="-4.28962018583184E-22"
        izz="0.000444744745767282" />
    </inertial>
    <visual>
      <origin
        xyz="0 0 0"
        rpy="0 0 0" />
      <geometry>
        <mesh
          filename="package://roller_3rd/meshes/leg2_2_Link.STL" />
      </geometry>
      <material
        name="">
        <color
          rgba="1 1 1 1" />
      </material>
    </visual>
    <collision>
      <origin
        xyz="0 0 0"
        rpy="0 0 0" />
      <geometry>
        <mesh
          filename="package://roller_3rd/meshes/leg2_2_Link.STL" />
      </geometry>
    </collision>
  </link>
  <joint
    name="leg2_2_joint"
    type="prismatic">
    <origin
      xyz="0.270650697408827 0 0.015"
      rpy="0 0 0" />
    <parent
      link="leg2_1_Link" />
    <child
      link="leg2_2_Link" />
    <axis
      xyz="1 0 0" />
    <limit
      lower="0"
      upper="0.2"
      effort="0"
      velocity="3" />
    <dynamics damping="${Damping}" friction="${Friction}"/>
  </joint>
  <link
    name="leg2_3_Link">
    <inertial>
      <origin
        xyz="-8.67361737988404E-19 0 0"
        rpy="0 0 0" />
      <mass
        value="0.440608369665969" />
      <inertia
        ixx="0.00059757510135947"
        ixy="-6.00188944931833E-20"
        ixz="5.02128542454901E-21"
        iyy="0.00059757510135947"
        iyz="-2.43945488809238E-19"
        izz="0.00112905894726905" />
    </inertial>
    <visual>
      <origin
        xyz="0 0 0"
        rpy="0 0 0" />
      <geometry>
        <mesh
          filename="package://roller_3rd/meshes/leg2_3_Link.STL" />
      </geometry>
      <material
        name="">
        <color
          rgba="1 1 1 1" />
      </material>
    </visual>
    <collision>
      <origin
        xyz="0 0 0"
        rpy="0 0 0" />
      <geometry>
        <mesh
          filename="package://roller_3rd/meshes/leg2_3_Link.STL" />
      </geometry>
    </collision>
  </link>
  <joint
    name="leg2_3_joint"
    type="continuous">
    <origin
      xyz="0.105 0 -0.015"
      rpy="0 -1.5707963267949 0" />
    <parent
      link="leg2_2_Link" />
    <child
      link="leg2_3_Link" />
    <axis
      xyz="0 0 -1" />
    <dynamics damping="${Damping}" friction="${Friction}"/>
  </joint>
  <link
    name="leg3_1_Link">
    <inertial>
      <origin
        xyz="0.0229508358714045 -1.38777878078145E-17 8.67361737988404E-18"
        rpy="0 0 0" />
      <mass
        value="0.350969420203415" />
      <inertia
        ixx="0.000303791179644144"
        ixy="1.35525271560688E-20"
        ixz="-9.11069723201289E-20"
        iyy="0.00119023844034398"
        iyz="2.09135589396779E-20"
        izz="0.0010182423165243" />
    </inertial>
    <visual>
      <origin
        xyz="0 0 0"
        rpy="0 0 0" />
      <geometry>
        <mesh
          filename="package://roller_3rd/meshes/leg3_1_Link.STL" />
      </geometry>
      <material
        name="">
        <color
          rgba="1 1 1 1" />
      </material>
    </visual>
    <collision>
      <origin
        xyz="0 0 0"
        rpy="0 0 0" />
      <geometry>
        <mesh
          filename="package://roller_3rd/meshes/leg3_1_Link.STL" />
      </geometry>
    </collision>
  </link>
  <joint
    name="leg3_1_joint"
    type="continuous">
    <origin
      xyz="0.152196098258253 0.0996390580196404 0"
      rpy="0 0 2.55359005004223" />
    <parent
      link="base_link" />
    <child
      link="leg3_1_Link" />
    <axis
      xyz="0 0 1" />
    <limit
      lower="0"
      upper="6.2"
      effort="0"
      velocity="3" />
    <dynamics damping="${Damping}" friction="${Friction}"/>
  </joint>
  <link
    name="leg3_2_Link">
    <inertial>
      <origin
        xyz="0.0200223800027241 2.77555756156289E-17 -0.015"
        rpy="0 0 0" />
      <mass
        value="0.111205750411731" />
      <inertia
        ixx="2.18856469213199E-05"
        ixy="-7.87740640946499E-20"
        ixz="-5.46487573117288E-21"
        iyy="0.000444744745767282"
        iyz="5.43866104817508E-21"
        izz="0.000444744745767282" />
    </inertial>
    <visual>
      <origin
        xyz="0 0 0"
        rpy="0 0 0" />
      <geometry>
        <mesh
          filename="package://roller_3rd/meshes/leg3_2_Link.STL" />
      </geometry>
      <material
        name="">
        <color
          rgba="1 1 1 1" />
      </material>
    </visual>
    <collision>
      <origin
        xyz="0 0 0"
        rpy="0 0 0" />
      <geometry>
        <mesh
          filename="package://roller_3rd/meshes/leg3_2_Link.STL" />
      </geometry>
    </collision>
  </link>
  <joint
    name="leg3_2_joint"
    type="prismatic">
    <origin
      xyz="0.270650697408827 0 0.015"
      rpy="0 0 0" />
    <parent
      link="leg3_1_Link" />
    <child
      link="leg3_2_Link" />
    <axis
      xyz="-1 0 0" />
    <limit
      lower="0"
      upper="0.2"
      effort="0"
      velocity="3" />
    <dynamics damping="${Damping}" friction="${Friction}"/>
  </joint>
  <link
    name="leg3_3_Link">
    <inertial>
      <origin
        xyz="1.73472347597681E-18 0 0"
        rpy="0 0 0" />
      <mass
        value="0.440608369665969" />
      <inertia
        ixx="0.00059757510135947"
        ixy="3.73750468809786E-20"
        ixz="-2.80484915575377E-20"
        iyy="0.000597575101359471"
        iyz="-5.42101086242752E-20"
        izz="0.00112905894726905" />
    </inertial>
    <visual>
      <origin
        xyz="0 0 0"
        rpy="0 0 0" />
      <geometry>
        <mesh
          filename="package://roller_3rd/meshes/leg3_3_Link.STL" />
      </geometry>
      <material
        name="">
        <color
          rgba="1 1 1 1" />
      </material>
    </visual>
    <collision>
      <origin
        xyz="0 0 0"
        rpy="0 0 0" />
      <geometry>
        <mesh
          filename="package://roller_3rd/meshes/leg3_3_Link.STL" />
      </geometry>
    </collision>
  </link>
  <joint
    name="leg3_3_joint"
    type="continuous">
    <origin
      xyz="0.105 0 -0.015"
      rpy="0 -1.5707963267949 0" />
    <parent
      link="leg3_2_Link" />
    <child
      link="leg3_3_Link" />
    <axis
      xyz="0 0 -1" />
    <dynamics damping="${Damping}" friction="${Friction}"/>
  </joint>
  <link
    name="leg4_1_Link">
    <inertial>
      <origin
        xyz="0.0229508358714045 -5.55111512312578E-17 7.80625564189563E-18"
        rpy="0 0 0" />
      <mass
        value="0.350969420203415" />
      <inertia
        ixx="0.000303791179644144"
        ixy="-4.47233396150271E-19"
        ixz="-8.15651439121812E-20"
        iyy="0.00119023844034398"
        iyz="-4.73281423090706E-21"
        izz="0.0010182423165243" />
    </inertial>
    <visual>
      <origin
        xyz="0 0 0"
        rpy="0 0 0" />
      <geometry>
        <mesh
          filename="package://roller_3rd/meshes/leg4_1_Link.STL" />
      </geometry>
      <material
        name="">
        <color
          rgba="1 1 1 1" />
      </material>
    </visual>
    <collision>
      <origin
        xyz="0 0 0"
        rpy="0 0 0" />
      <geometry>
        <mesh
          filename="package://roller_3rd/meshes/leg4_1_Link.STL" />
      </geometry>
    </collision>
  </link>
  <joint
    name="leg4_1_joint"
    type="continuous">
    <origin
      xyz="0.152196098258253 -0.0996390580196402 0"
      rpy="0 0 -2.55359005004222" />
    <parent
      link="base_link" />
    <child
      link="leg4_1_Link" />
    <axis
      xyz="0 0 1" />
    <limit
      lower="0"
      upper="6.2"
      effort="0"
      velocity="3" />
    <dynamics damping="${Damping}" friction="${Friction}"/>
  </joint>
  <link
    name="leg4_2_Link">
    <inertial>
      <origin
        xyz="0.0200223800027241 -5.55111512312578E-17 -0.015"
        rpy="0 0 0" />
      <mass
        value="0.111205750411731" />
      <inertia
        ixx="2.18856469213198E-05"
        ixy="-7.96210970419042E-20"
        ixz="1.16988580810433E-20"
        iyy="0.000444744745767282"
        iyz="-4.59912379973578E-21"
        izz="0.000444744745767282" />
    </inertial>
    <visual>
      <origin
        xyz="0 0 0"
        rpy="0 0 0" />
      <geometry>
        <mesh
          filename="package://roller_3rd/meshes/leg4_2_Link.STL" />
      </geometry>
      <material
        name="">
        <color
          rgba="1 1 1 1" />
      </material>
    </visual>
    <collision>
      <origin
        xyz="0 0 0"
        rpy="0 0 0" />
      <geometry>
        <mesh
          filename="package://roller_3rd/meshes/leg4_2_Link.STL" />
      </geometry>
    </collision>
  </link>
  <joint
    name="leg4_2_joint"
    type="prismatic">
    <origin
      xyz="0.270650697408827 0 0.0149999999999999"
      rpy="0 0 0" />
    <parent
      link="leg4_1_Link" />
    <child
      link="leg4_2_Link" />
    <axis
      xyz="-1 0 0" />
    <limit
      lower="0"
      upper="0.2"
      effort="0"
      velocity="3" />
    <dynamics damping="${Damping}" friction="${Friction}"/>
  </joint>
  <link
    name="leg4_3_Link">
    <inertial>
      <origin
        xyz="-1.73472347597681E-18 -1.11022302462516E-16 1.11022302462516E-16"
        rpy="0 0 0" />
      <mass
        value="0.440608369665969" />
      <inertia
        ixx="0.000597575101359471"
        ixy="1.99001385197597E-19"
        ixz="-1.30912365153136E-20"
        iyy="0.000597575101359471"
        iyz="0"
        izz="0.00112905894726905" />
    </inertial>
    <visual>
      <origin
        xyz="0 0 0"
        rpy="0 0 0" />
      <geometry>
        <mesh
          filename="package://roller_3rd/meshes/leg4_3_Link.STL" />
      </geometry>
      <material
        name="">
        <color
          rgba="1 1 1 1" />
      </material>
    </visual>
    <collision>
      <origin
        xyz="0 0 0"
        rpy="0 0 0" />
      <geometry>
        <mesh
          filename="package://roller_3rd/meshes/leg4_3_Link.STL" />
      </geometry>
    </collision>
  </link>
  <joint
    name="leg4_3_joint"
    type="continuous">
    <origin
      xyz="0.105 0 -0.0149999999999999"
      rpy="0 -1.5707963267949 0" />
    <parent
      link="leg4_2_Link" />
    <child
      link="leg4_3_Link" />
    <axis
      xyz="0 0 -1" />
    <dynamics damping="${Damping}" friction="${Friction}"/>
  </joint>
</robot>